[Config file]: C:\Users\Lenovo\AppData\Local\Temp\tmpdcz0xclx
[Unhandled Error] AssertionError('devicePixelRatio is not 1.0')
Traceback (most recent call last):
  File "D:\project\visualwebarena\browser_env\processors.py", line 740, in process
    browser_info = self.fetch_browser_info(page)
                   ^^^^^^^^^^^^^^^^^^^^^^^^^^^^^
  File "D:\project\visualwebarena\browser_env\processors.py", line 140, in fetch_browser_info
    assert device_pixel_ratio == 1.0, "devicePixelRatio is not 1.0"
AssertionError: devicePixelRatio is not 1.0

During handling of the above exception, another exception occurred:

Traceback (most recent call last):
  File "D:\project\visualwebarena\run_demo.py", line 321, in test
    obs, info = env.reset(options={"config_file": config_file})
                ^^^^^^^^^^^^^^^^^^^^^^^^^^^^^^^^^^^^^^^^^^^^^^^
  File "<@beartype(browser_env.envs.ScriptBrowserEnv.reset) at 0x1fb5b6813a0>", line 51, in reset
  File "D:\project\visualwebarena\browser_env\envs.py", line 255, in reset
    observation = self._get_obs()
                  ^^^^^^^^^^^^^^^
  File "D:\project\visualwebarena\browser_env\envs.py", line 220, in _get_obs
    obs = self.observation_handler.get_observation(self.page)
          ^^^^^^^^^^^^^^^^^^^^^^^^^^^^^^^^^^^^^^^^^^^^^^^^^^^
  File "D:\project\visualwebarena\browser_env\processors.py", line 1266, in get_observation
    text_obs = self.text_processor.process(page)
               ^^^^^^^^^^^^^^^^^^^^^^^^^^^^^^^^^
  File "D:\project\visualwebarena\browser_env\processors.py", line 743, in process
    browser_info = self.fetch_browser_info(page)
                   ^^^^^^^^^^^^^^^^^^^^^^^^^^^^^
  File "D:\project\visualwebarena\browser_env\processors.py", line 140, in fetch_browser_info
    assert device_pixel_ratio == 1.0, "devicePixelRatio is not 1.0"
AssertionError: devicePixelRatio is not 1.0
[Config file]: C:\Users\Lenovo\AppData\Local\Temp\tmpaw8n0ym0
[Unhandled Error] AssertionError('devicePixelRatio is not 1.0')
Traceback (most recent call last):
  File "D:\project\visualwebarena\browser_env\processors.py", line 740, in process
    browser_info = self.fetch_browser_info(page)
                   ^^^^^^^^^^^^^^^^^^^^^^^^^^^^^
  File "D:\project\visualwebarena\browser_env\processors.py", line 140, in fetch_browser_info
    assert device_pixel_ratio == 1.0, "devicePixelRatio is not 1.0"
AssertionError: devicePixelRatio is not 1.0

During handling of the above exception, another exception occurred:

Traceback (most recent call last):
  File "D:\project\visualwebarena\run_demo.py", line 321, in test
    obs, info = env.reset(options={"config_file": config_file})
                ^^^^^^^^^^^^^^^^^^^^^^^^^^^^^^^^^^^^^^^^^^^^^^^
  File "<@beartype(browser_env.envs.ScriptBrowserEnv.reset) at 0x1c71d6413a0>", line 51, in reset
  File "D:\project\visualwebarena\browser_env\envs.py", line 255, in reset
    observation = self._get_obs()
                  ^^^^^^^^^^^^^^^
  File "D:\project\visualwebarena\browser_env\envs.py", line 220, in _get_obs
    obs = self.observation_handler.get_observation(self.page)
          ^^^^^^^^^^^^^^^^^^^^^^^^^^^^^^^^^^^^^^^^^^^^^^^^^^^
  File "D:\project\visualwebarena\browser_env\processors.py", line 1266, in get_observation
    text_obs = self.text_processor.process(page)
               ^^^^^^^^^^^^^^^^^^^^^^^^^^^^^^^^^
  File "D:\project\visualwebarena\browser_env\processors.py", line 743, in process
    browser_info = self.fetch_browser_info(page)
                   ^^^^^^^^^^^^^^^^^^^^^^^^^^^^^
  File "D:\project\visualwebarena\browser_env\processors.py", line 140, in fetch_browser_info
    assert device_pixel_ratio == 1.0, "devicePixelRatio is not 1.0"
AssertionError: devicePixelRatio is not 1.0
[Config file]: C:\Users\Lenovo\AppData\Local\Temp\tmp0o715j2w
[Unhandled Error] AssertionError('devicePixelRatio is not 1.0')
Traceback (most recent call last):
  File "D:\project\visualwebarena\browser_env\processors.py", line 740, in process
    browser_info = self.fetch_browser_info(page)
                   ^^^^^^^^^^^^^^^^^^^^^^^^^^^^^
  File "D:\project\visualwebarena\browser_env\processors.py", line 140, in fetch_browser_info
    assert device_pixel_ratio == 1.0, "devicePixelRatio is not 1.0"
AssertionError: devicePixelRatio is not 1.0

During handling of the above exception, another exception occurred:

Traceback (most recent call last):
  File "D:\project\visualwebarena\run_demo.py", line 321, in test
    obs, info = env.reset(options={"config_file": config_file})
                ^^^^^^^^^^^^^^^^^^^^^^^^^^^^^^^^^^^^^^^^^^^^^^^
  File "<@beartype(browser_env.envs.ScriptBrowserEnv.reset) at 0x288de09d3a0>", line 51, in reset
  File "D:\project\visualwebarena\browser_env\envs.py", line 255, in reset
    observation = self._get_obs()
                  ^^^^^^^^^^^^^^^
  File "D:\project\visualwebarena\browser_env\envs.py", line 220, in _get_obs
    obs = self.observation_handler.get_observation(self.page)
          ^^^^^^^^^^^^^^^^^^^^^^^^^^^^^^^^^^^^^^^^^^^^^^^^^^^
  File "D:\project\visualwebarena\browser_env\processors.py", line 1266, in get_observation
    text_obs = self.text_processor.process(page)
               ^^^^^^^^^^^^^^^^^^^^^^^^^^^^^^^^^
  File "D:\project\visualwebarena\browser_env\processors.py", line 743, in process
    browser_info = self.fetch_browser_info(page)
                   ^^^^^^^^^^^^^^^^^^^^^^^^^^^^^
  File "D:\project\visualwebarena\browser_env\processors.py", line 140, in fetch_browser_info
    assert device_pixel_ratio == 1.0, "devicePixelRatio is not 1.0"
AssertionError: devicePixelRatio is not 1.0
[Config file]: C:\Users\Lenovo\AppData\Local\Temp\tmplqdz68ft
[Unhandled Error] AssertionError('devicePixelRatio is not 1.0')
Traceback (most recent call last):
  File "D:\project\visualwebarena\browser_env\processors.py", line 740, in process
    browser_info = self.fetch_browser_info(page)
                   ^^^^^^^^^^^^^^^^^^^^^^^^^^^^^
  File "D:\project\visualwebarena\browser_env\processors.py", line 140, in fetch_browser_info
    assert device_pixel_ratio == 1.0, "devicePixelRatio is not 1.0"
AssertionError: devicePixelRatio is not 1.0

During handling of the above exception, another exception occurred:

Traceback (most recent call last):
  File "D:\project\visualwebarena\run_demo.py", line 321, in test
    obs, info = env.reset(options={"config_file": config_file})
                ^^^^^^^^^^^^^^^^^^^^^^^^^^^^^^^^^^^^^^^^^^^^^^^
  File "<@beartype(browser_env.envs.ScriptBrowserEnv.reset) at 0x2182b05d4e0>", line 51, in reset
  File "D:\project\visualwebarena\browser_env\envs.py", line 255, in reset
    observation = self._get_obs()
                  ^^^^^^^^^^^^^^^
  File "D:\project\visualwebarena\browser_env\envs.py", line 220, in _get_obs
    obs = self.observation_handler.get_observation(self.page)
          ^^^^^^^^^^^^^^^^^^^^^^^^^^^^^^^^^^^^^^^^^^^^^^^^^^^
  File "D:\project\visualwebarena\browser_env\processors.py", line 1266, in get_observation
    text_obs = self.text_processor.process(page)
               ^^^^^^^^^^^^^^^^^^^^^^^^^^^^^^^^^
  File "D:\project\visualwebarena\browser_env\processors.py", line 743, in process
    browser_info = self.fetch_browser_info(page)
                   ^^^^^^^^^^^^^^^^^^^^^^^^^^^^^
  File "D:\project\visualwebarena\browser_env\processors.py", line 140, in fetch_browser_info
    assert device_pixel_ratio == 1.0, "devicePixelRatio is not 1.0"
AssertionError: devicePixelRatio is not 1.0
[Config file]: C:\Users\Lenovo\AppData\Local\Temp\tmp7qg4kpsi
[Unhandled Error] Exception('Maximum number of retries (3) exceeded.')
Traceback (most recent call last):
  File "D:\project\visualwebarena\llms\providers\openai_utils.py", line 49, in wrapper
    return func(*args, **kwargs)
           ^^^^^^^^^^^^^^^^^^^^^
  File "D:\project\visualwebarena\llms\providers\openai_utils.py", line 263, in generate_from_openai_chat_completion
    response = client.chat.completions.create(
               ^^^^^^^^^^^^^^^^^^^^^^^^^^^^^^^
  File "D:\project\visualwebarena\venv\Lib\site-packages\openai\_utils\_utils.py", line 299, in wrapper
    return func(*args, **kwargs)
           ^^^^^^^^^^^^^^^^^^^^^
  File "D:\project\visualwebarena\venv\Lib\site-packages\openai\resources\chat\completions.py", line 598, in create
    return self._post(
           ^^^^^^^^^^^
  File "D:\project\visualwebarena\venv\Lib\site-packages\openai\_base_client.py", line 1063, in post
    return cast(ResponseT, self.request(cast_to, opts, stream=stream, stream_cls=stream_cls))
                           ^^^^^^^^^^^^^^^^^^^^^^^^^^^^^^^^^^^^^^^^^^^^^^^^^^^^^^^^^^^^^^^^^
  File "D:\project\visualwebarena\venv\Lib\site-packages\openai\_base_client.py", line 842, in request
    return self._request(
           ^^^^^^^^^^^^^^
  File "D:\project\visualwebarena\venv\Lib\site-packages\openai\_base_client.py", line 885, in _request
    raise self._make_status_error_from_response(err.response) from None
openai.BadRequestError: Error code: 400 - {'error': {'code': 'data_inspection_failed', 'param': None, 'message': 'Input data may contain inappropriate content.', 'type': 'data_inspection_failed'}, 'id': 'chatcmpl-3115ed1e-4b59-4f69-810b-ab64d446e619', 'request_id': '3115ed1e-4b59-4f69-810b-ab64d446e619'}

During handling of the above exception, another exception occurred:

Traceback (most recent call last):
  File "D:\project\visualwebarena\run_demo.py", line 337, in test
    action = agent.next_action(
             ^^^^^^^^^^^^^^^^^^
  File "<@beartype(agent.agent.PromptAgent.next_action) at 0x21e351b1620>", line 135, in next_action
  File "D:\project\visualwebarena\agent\agent.py", line 173, in next_action
    response = call_llm(lm_config, prompt)
               ^^^^^^^^^^^^^^^^^^^^^^^^^^^
  File "D:\project\visualwebarena\llms\utils.py", line 28, in call_llm
    response = generate_from_openai_chat_completion(
               ^^^^^^^^^^^^^^^^^^^^^^^^^^^^^^^^^^^^^
  File "D:\project\visualwebarena\llms\providers\openai_utils.py", line 58, in wrapper
    raise Exception(
Exception: Maximum number of retries (3) exceeded.
[Config file]: C:\Users\Lenovo\AppData\Local\Temp\tmpjbwpjekg
[Unhandled Error] Exception('Maximum number of retries (3) exceeded.')
Traceback (most recent call last):
  File "D:\project\visualwebarena\llms\providers\openai_utils.py", line 49, in wrapper
    return func(*args, **kwargs)
           ^^^^^^^^^^^^^^^^^^^^^
  File "D:\project\visualwebarena\llms\providers\openai_utils.py", line 263, in generate_from_openai_chat_completion
    response = client.chat.completions.create(
               ^^^^^^^^^^^^^^^^^^^^^^^^^^^^^^^
  File "D:\project\visualwebarena\venv\Lib\site-packages\openai\_utils\_utils.py", line 299, in wrapper
    return func(*args, **kwargs)
           ^^^^^^^^^^^^^^^^^^^^^
  File "D:\project\visualwebarena\venv\Lib\site-packages\openai\resources\chat\completions.py", line 598, in create
    return self._post(
           ^^^^^^^^^^^
  File "D:\project\visualwebarena\venv\Lib\site-packages\openai\_base_client.py", line 1063, in post
    return cast(ResponseT, self.request(cast_to, opts, stream=stream, stream_cls=stream_cls))
                           ^^^^^^^^^^^^^^^^^^^^^^^^^^^^^^^^^^^^^^^^^^^^^^^^^^^^^^^^^^^^^^^^^
  File "D:\project\visualwebarena\venv\Lib\site-packages\openai\_base_client.py", line 842, in request
    return self._request(
           ^^^^^^^^^^^^^^
  File "D:\project\visualwebarena\venv\Lib\site-packages\openai\_base_client.py", line 885, in _request
    raise self._make_status_error_from_response(err.response) from None
openai.BadRequestError: Error code: 400 - {'error': {'code': 'data_inspection_failed', 'param': None, 'message': 'Input data may contain inappropriate content.', 'type': 'data_inspection_failed'}, 'id': 'chatcmpl-f9e28765-1cc2-4b0d-8f10-569e978106ff', 'request_id': 'f9e28765-1cc2-4b0d-8f10-569e978106ff'}

During handling of the above exception, another exception occurred:

Traceback (most recent call last):
  File "D:\project\visualwebarena\run_demo.py", line 337, in test
    action = agent.next_action(
             ^^^^^^^^^^^^^^^^^^
  File "<@beartype(agent.agent.PromptAgent.next_action) at 0x1851f4e14e0>", line 135, in next_action
  File "D:\project\visualwebarena\agent\agent.py", line 173, in next_action
    response = call_llm(lm_config, prompt)
               ^^^^^^^^^^^^^^^^^^^^^^^^^^^
  File "D:\project\visualwebarena\llms\utils.py", line 28, in call_llm
    response = generate_from_openai_chat_completion(
               ^^^^^^^^^^^^^^^^^^^^^^^^^^^^^^^^^^^^^
  File "D:\project\visualwebarena\llms\providers\openai_utils.py", line 58, in wrapper
    raise Exception(
Exception: Maximum number of retries (3) exceeded.
[Config file]: C:\Users\Lenovo\AppData\Local\Temp\tmpqm48om_m
[Unhandled Error] Exception('Maximum number of retries (3) exceeded.')
Traceback (most recent call last):
  File "D:\project\visualwebarena\llms\providers\openai_utils.py", line 49, in wrapper
    return func(*args, **kwargs)
           ^^^^^^^^^^^^^^^^^^^^^
  File "D:\project\visualwebarena\llms\providers\openai_utils.py", line 263, in generate_from_openai_chat_completion
    response = client.chat.completions.create(
               ^^^^^^^^^^^^^^^^^^^^^^^^^^^^^^^
  File "D:\project\visualwebarena\venv\Lib\site-packages\openai\_utils\_utils.py", line 299, in wrapper
    return func(*args, **kwargs)
           ^^^^^^^^^^^^^^^^^^^^^
  File "D:\project\visualwebarena\venv\Lib\site-packages\openai\resources\chat\completions.py", line 598, in create
    return self._post(
           ^^^^^^^^^^^
  File "D:\project\visualwebarena\venv\Lib\site-packages\openai\_base_client.py", line 1063, in post
    return cast(ResponseT, self.request(cast_to, opts, stream=stream, stream_cls=stream_cls))
                           ^^^^^^^^^^^^^^^^^^^^^^^^^^^^^^^^^^^^^^^^^^^^^^^^^^^^^^^^^^^^^^^^^
  File "D:\project\visualwebarena\venv\Lib\site-packages\openai\_base_client.py", line 842, in request
    return self._request(
           ^^^^^^^^^^^^^^
  File "D:\project\visualwebarena\venv\Lib\site-packages\openai\_base_client.py", line 885, in _request
    raise self._make_status_error_from_response(err.response) from None
openai.BadRequestError: Error code: 400 - {'error': {'code': 'data_inspection_failed', 'param': None, 'message': 'Input data may contain inappropriate content.', 'type': 'data_inspection_failed'}, 'id': 'chatcmpl-7c7fe902-6f08-46c8-bb73-c02ab2602b49', 'request_id': '7c7fe902-6f08-46c8-bb73-c02ab2602b49'}

During handling of the above exception, another exception occurred:

Traceback (most recent call last):
  File "D:\project\visualwebarena\run_demo.py", line 337, in test
    action = agent.next_action(
             ^^^^^^^^^^^^^^^^^^
  File "<@beartype(agent.agent.PromptAgent.next_action) at 0x1d7251d1620>", line 135, in next_action
  File "D:\project\visualwebarena\agent\agent.py", line 173, in next_action
    response = call_llm(lm_config, prompt)
               ^^^^^^^^^^^^^^^^^^^^^^^^^^^
  File "D:\project\visualwebarena\llms\utils.py", line 28, in call_llm
    response = generate_from_openai_chat_completion(
               ^^^^^^^^^^^^^^^^^^^^^^^^^^^^^^^^^^^^^
  File "D:\project\visualwebarena\llms\providers\openai_utils.py", line 58, in wrapper
    raise Exception(
Exception: Maximum number of retries (3) exceeded.
